// @flow
import K from './k';

/**
 * A utility function used for wrapping async code that would otherwise need a
 * try-catch block.
 *
 * V8 deoptimizes functions when running into try-catch catch due to the
 * unpredictable nature of the code. The `tryCatch` utility function is a way
 * to "have your cake and eat it too". Since the inner function (`fn`) will not
 * become deoptimized by V8 for including a standard try-catch block, we don't
 * have to sacrifice as much perf for error handling expensive computations.
 *
 * The `tryCatch` utility is also very useful when you want to perform a noop
 * when an error is thrown as the catch argument (`rescue`) is optional unlike
 * a traditional try-catch block.
 *
 * @example
 * tryCatch(() => {
 *   const n = Math.floor(Math.random() * 6);
 *
 *   if (n >= 4) {
 *     throw new Error('You lose!');
 *   } else {
 *     return Promise.resolve(n);
 *   }
 * }, err => {
 *   console.error(err);
 * }).then(luckyNumber => {
 *   console.log(`Your lucky number is ${luckyNumber}.`);
 * });
 *
 * @private
 */
export default async function tryCatch(
  fn: Function,
  rescue: Function = K
): Promise<any> {
  try {
    return await fn();
  } catch (err) {
    await rescue(err);
  }
}

/**
 * A syncronous implementation of the `tryCatch` utility.
 *
 * @example
 * const luckyNumber = tryCatchSync(() => {
 *   const n = Math.floor(Math.random() * 6);
 *
 *   if (n >= 4) {
 *     throw new Error('You lose!');
 *   } else {
 *     return n;
 *   }
 * }, err => {
 *   console.error(err);
 * });
 *
 * if (luckyNumber) {
 *   console.log(`Your lucky number is ${luckyNumber}.`);
 * }
 *
 * @private
 */
 export function tryCatchSync(fn: Function, rescue: Function = K): any {
  try {
    return fn();
  } catch (err) {
    rescue(err);
  }
}
